Workbook
Name _01: #REF!
Name _02: #REF!
Name _03: #REF!
Name _04: #REF!
Name _05: #REF!
Name _06: #REF!
Name _10: #REF!
Name _2: #N/A
Name _3: #N/A
Name _apt001: #REF!
Name _apt002: #REF!
Name _apt003: #REF!
Name _apt1: #REF!
Name _APT101: #REF!
Name _APT102: #REF!
Name _APT103: #REF!
Name _APT104: #REF!
Name _APT105: #REF!
Name _APT106: #REF!
Name _APT107: #REF!
Name _APT108: #REF!
Name _APT109: #REF!
Name _APT110: #REF!
Name _apt111: #REF!
Name _apt112: #REF!
Name _apt113: #REF!
Name _apt201: #REF!
Name _apt202: #REF!
Name _apt203: #REF!
Name _apt301: #REF!
Name _apt302: #REF!
Name _apt303: #REF!
Name _apt401: #REF!
Name _apt402: #REF!
Name _apt403: #REF!
Name _apt404: #REF!
Name _apt405: #REF!
Name _apt406: #REF!
Name _apt407: #REF!
Name _APT501: #REF!
Name _APT502: #REF!
Name _APT503: #REF!
Name _APT504: #REF!
Name _APT505: #REF!
Name _APT506: #REF!
Name _APT507: #REF!
Name _APT508: #REF!
Name _APT509: #REF!
Name _APT510: #REF!
Name _bok1: #REF!
Name _bok2: #REF!
Name _PR01: #REF!
Name _PRT2: #REF!
Name _PRT3: #REF!
Name \0: #REF!
Name \1111: #REF!
Name \a: #REF!
Name \b: #REF!
Name \c: #REF!
Name \d: #REF!

Sheet 바닥판
A1: 소재 | B1: 유형 | C1: 형태 | D1: 용도 | E1: 경계 | F1: 욕실폭 | G1: 욕실길이 | H1: 세면부폭 | I1: 세면부길이 | J1: 샤워부폭 | K1: 샤워부길이 | L1: 세면부바닥판 단가 | M1: 샤워부바닥판 단가 | N1: 소계
A2: GRP | B2: 기본형 | C2: 코너형 | D2: 샤워형 | E2: 구분 | F2: 1300 | G2: 1900 | H2: 1300 | I2: 1300 | J2: 850 | K2: 600 | L2: =바닥판단가!G2 -> 51610 | M2: =바닥판단가!G16 -> 20666 | N2: =바닥판단가!G2 + 바닥판단가!G16 -> 72276
A3: GRP | B3: 기본형 | C3: 코너형 | D3: 샤워형 | E3: 구분 | F3: 1300 | G3: 1900 | H3: 1300 | I3: 1300 | J3: 900 | K3: 600 | L3: =바닥판단가!G2 -> 51610 | M3: =바닥판단가!G17 -> 21190 | N3: =바닥판단가!G2 + 바닥판단가!G17 -> 72800
A4: GRP | B4: 기본형 | C4: 코너형 | D4: 샤워형 | E4: 구분 | F4: 1300 | G4: 2000 | H4: 1300 | I4: 1300 | J4: 900 | K4: 700 | L4: =바닥판단가!G2 -> 51610 | M4: =바닥판단가!G18 -> 22342 | N4: =바닥판단가!G2 + 바닥판단가!G18 -> 73952
A5: GRP | B5: 기본형 | C5: 코너형 | D5: 샤워형 | E5: 구분 | F5: 1300 | G5: 2000 | H5: 1300 | I5: 1400 | J5: 850 | K5: 600 | L5: =바닥판단가!G3 -> 53600 | M5: =바닥판단가!G16 -> 20666 | N5: =바닥판단가!G3 + 바닥판단가!G16 -> 74266
A6: GRP | B6: 기본형 | C6: 코너형 | D6: 샤워형 | E6: 구분 | F6: 1300 | G6: 2000 | H6: 1300 | I6: 1400 | J6: 900 | K6: 600 | L6: =바닥판단가!G3 -> 53600 | M6: =바닥판단가!G17 -> 21190 | N6: =바닥판단가!G3 + 바닥판단가!G17 -> 74790
A7: GRP | B7: 기본형 | C7: 코너형 | D7: 샤워형 | E7: 구분 | F7: 1300 | G7: 2100 | H7: 1300 | I7: 1300 | J7: 900 | K7: 800 | L7: =바닥판단가!G2 -> 51610 | M7: =바닥판단가!G19 -> 23494 | N7: =바닥판단가!G2 + 바닥판단가!G19 -> 75104
A8: GRP | B8: 기본형 | C8: 코너형 | D8: 샤워형 | E8: 구분 | F8: 1300 | G8: 2100 | H8: 1300 | I8: 1400 | J8: 900 | K8: 700 | L8: =바닥판단가!G3 -> 53600 | M8: =바닥판단가!G18 -> 22342 | N8: =바닥판단가!G3 + 바닥판단가!G18 -> 75942
A9: GRP | B9: 기본형 | C9: 코너형 | D9: 샤워형 | E9: 구분 | F9: 1300 | G9: 2100 | H9: 1300 | I9: 1500 | J9: 850 | K9: 600 | L9: =바닥판단가!G4 -> 55485 | M9: =바닥판단가!G16 -> 20666 | N9: =바닥판단가!G4 + 바닥판단가!G16 -> 76151
A10: GRP | B10: 기본형 | C10: 코너형 | D10: 샤워형 | E10: 구분 | F10: 1300 | G10: 2100 | H10: 1300 | I10: 1500 | J10: 900 | K10: 600 | L10: =바닥판단가!G4 -> 55485 | M10: =바닥판단가!G17 -> 21190 | N10: =바닥판단가!G4 + 바닥판단가!G17 -> 76675
A11: GRP | B11: 기본형 | C11: 코너형 | D11: 샤워형 | E11: 구분 | F11: 1300 | G11: 2200 | H11: 1300 | I11: 1300 | J11: 900 | K11: 900 | L11: =바닥판단가!G2 -> 51610 | M11: =바닥판단가!G20 -> 25066 | N11: =바닥판단가!G2 + 바닥판단가!G20 -> 76676
A12: GRP | B12: 기본형 | C12: 코너형 | D12: 샤워형 | E12: 구분 | F12: 1300 | G12: 2200 | H12: 1300 | I12: 1300 | J12: 1000 | K12: 900 | L12: =바닥판단가!G2 -> 51610 | M12: =바닥판단가!G23 -> 27161 | N12: =바닥판단가!G2 + 바닥판단가!G23 -> 78771
A13: GRP | B13: 기본형 | C13: 코너형 | D13: 샤워형 | E13: 구분 | F13: 1300 | G13: 2200 | H13: 1300 | I13: 1400 | J13: 900 | K13: 800 | L13: =바닥판단가!G3 -> 53600 | M13: =바닥판단가!G19 -> 23494 | N13: =바닥판단가!G3 + 바닥판단가!G19 -> 77094
A14: GRP | B14: 기본형 | C14: 코너형 | D14: 샤워형 | E14: 구분 | F14: 1300 | G14: 2200 | H14: 1300 | I14: 1500 | J14: 900 | K14: 700 | L14: =바닥판단가!G4 -> 55485 | M14: =바닥판단가!G18 -> 22342 | N14: =바닥판단가!G4 + 바닥판단가!G18 -> 77827
A15: GRP | B15: 기본형 | C15: 코너형 | D15: 샤워형 | E15: 구분 | F15: 1300 | G15: 2200 | H15: 1300 | I15: 1600 | J15: 850 | K15: 600 | L15: =바닥판단가!G5 -> 57790 | M15: =바닥판단가!G16 -> 20666 | N15: =바닥판단가!G5 + 바닥판단가!G16 -> 78456
A16: GRP | B16: 기본형 | C16: 코너형 | D16: 샤워형 | E16: 구분 | F16: 1300 | G16: 2200 | H16: 1300 | I16: 1600 | J16: 900 | K16: 600 | L16: =바닥판단가!G5 -> 57790 | M16: =바닥판단가!G17 -> 21190 | N16: =바닥판단가!G5 + 바닥판단가!G17 -> 78980
A17: GRP | B17: 기본형 | C17: 코너형 | D17: 샤워형 | E17: 구분 | F17: 1300 | G17: 2300 | H17: 1300 | I17: 1300 | J17: 1000 | K17: 1000 | L17: =바닥판단가!G2 -> 51610 | M17: =바닥판단가!G24 -> 29256 | N17: =바닥판단가!G2 + 바닥판단가!G24 -> 80866
A18: GRP | B18: 기본형 | C18: 코너형 | D18: 샤워형 | E18: 구분 | F18: 1300 | G18: 2300 | H18: 1300 | I18: 1400 | J18: 900 | K18: 900 | L18: =바닥판단가!G3 -> 53600 | M18: =바닥판단가!G20 -> 25066 | N18: =바닥판단가!G3 + 바닥판단가!G20 -> 78666
A19: GRP | B19: 기본형 | C19: 코너형 | D19: 샤워형 | E19: 구분 | F19: 1300 | G19: 2300 | H19: 1300 | I19: 1400 | J19: 1000 | K19: 900 | L19: =바닥판단가!G3 -> 53600 | M19: =바닥판단가!G23 -> 27161 | N19: =바닥판단가!G3 + 바닥판단가!G23 -> 80761
A20: GRP | B20: 기본형 | C20: 코너형 | D20: 샤워형 | E20: 구분 | F20: 1300 | G20: 2300 | H20: 1300 | I20: 1500 | J20: 900 | K20: 800 | L20: =바닥판단가!G4 -> 55485 | M20: =바닥판단가!G19 -> 23494 | N20: =바닥판단가!G4 + 바닥판단가!G19 -> 78979
A21: GRP | B21: 기본형 | C21: 코너형 | D21: 샤워형 | E21: 구분 | F21: 1300 | G21: 2300 | H21: 1300 | I21: 1600 | J21: 900 | K21: 700 | L21: =바닥판단가!G5 -> 57790 | M21: =바닥판단가!G18 -> 22342 | N21: =바닥판단가!G5 + 바닥판단가!G18 -> 80132
A22: GRP | B22: 기본형 | C22: 코너형 | D22: 샤워형 | E22: 구분 | F22: 1300 | G22: 2400 | H22: 1300 | I22: 1400 | J22: 1000 | K22: 1000 | L22: =바닥판단가!G3 -> 53600 | M22: =바닥판단가!G24 -> 29256 | N22: =바닥판단가!G3 + 바닥판단가!G24 -> 82856
A23: GRP | B23: 기본형 | C23: 코너형 | D23: 샤워형 | E23: 구분 | F23: 1300 | G23: 2400 | H23: 1300 | I23: 1500 | J23: 900 | K23: 900 | L23: =바닥판단가!G4 -> 55485 | M23: =바닥판단가!G20 -> 25066 | N23: =바닥판단가!G4 + 바닥판단가!G20 -> 80551
A24: GRP | B24: 기본형 | C24: 코너형 | D24: 샤워형 | E24: 구분 | F24: 1300 | G24: 2400 | H24: 1300 | I24: 1500 | J24: 1000 | K24: 900 | L24: =바닥판단가!G4 -> 55485 | M24: =바닥판단가!G23 -> 27161 | N24: =바닥판단가!G4 + 바닥판단가!G23 -> 82646
A25: GRP | B25: 기본형 | C25: 코너형 | D25: 샤워형 | E25: 구분 | F25: 1300 | G25: 2400 | H25: 1300 | I25: 1600 | J25: 900 | K25: 800 | L25: =바닥판단가!G5 -> 57790 | M25: =바닥판단가!G19 -> 23494 | N25: =바닥판단가!G5 + 바닥판단가!G19 -> 81284
A26: GRP | B26: 기본형 | C26: 코너형 | D26: 샤워형 | E26: 구분 | F26: 1300 | G26: 2500 | H26: 1300 | I26: 1500 | J26: 1000 | K26: 1000 | L26: =바닥판단가!G4 -> 55485 | M26: =바닥판단가!G24 -> 29256 | N26: =바닥판단가!G4 + 바닥판단가!G24 -> 84741
A27: GRP | B27: 기본형 | C27: 코너형 | D27: 샤워형 | E27: 구분 | F27: 1300 | G27: 2500 | H27: 1300 | I27: 1600 | J27: 900 | K27: 900 | L27: =바닥판단가!G5 -> 57790 | M27: =바닥판단가!G20 -> 25066 | N27: =바닥판단가!G5 + 바닥판단가!G20 -> 82856
A28: GRP | B28: 기본형 | C28: 코너형 | D28: 샤워형 | E28: 구분 | F28: 1300 | G28: 2500 | H28: 1300 | I28: 1600 | J28: 1000 | K28: 900 | L28: =바닥판단가!G5 -> 57790 | M28: =바닥판단가!G23 -> 27161 | N28: =바닥판단가!G5 + 바닥판단가!G23 -> 84951
A29: GRP | B29: 기본형 | C29: 코너형 | D29: 샤워형 | E29: 구분 | F29: 1400 | G29: 1900 | H29: 1400 | I29: 1300 | J29: 850 | K29: 600 | L29: =바닥판단가!G6 -> 53600 | M29: =바닥판단가!G16 -> 20666 | N29: =바닥판단가!G6 + 바닥판단가!G16 -> 74266
A30: GRP | B30: 기본형 | C30: 코너형 | D30: 샤워형 | E30: 구분 | F30: 1400 | G30: 1900 | H30: 1400 | I30: 1300 | J30: 900 | K30: 600 | L30: =바닥판단가!G6 -> 53600 | M30: =바닥판단가!G17 -> 21190 | N30: =바닥판단가!G6 + 바닥판단가!G17 -> 74790
A31: GRP | B31: 기본형 | C31: 코너형 | D31: 샤워형 | E31: 구분 | F31: 1400 | G31: 2000 | H31: 1400 | I31: 1300 | J31: 900 | K31: 700 | L31: =바닥판단가!G6 -> 53600 | M31: =바닥판단가!G18 -> 22342 | N31: =바닥판단가!G6 + 바닥판단가!G18 -> 75942
A32: GRP | B32: 기본형 | C32: 코너형 | D32: 샤워형 | E32: 구분 | F32: 1400 | G32: 2000 | H32: 1400 | I32: 1400 | J32: 850 | K32: 600 | L32: =바닥판단가!G7 -> 55695 | M32: =바닥판단가!G16 -> 20666 | N32: =바닥판단가!G7 + 바닥판단가!G16 -> 76361
A33: GRP | B33: 기본형 | C33: 코너형 | D33: 샤워형 | E33: 구분 | F33: 1400 | G33: 2000 | H33: 1400 | I33: 1400 | J33: 900 | K33: 600 | L33: =바닥판단가!G7 -> 55695 | M33: =바닥판단가!G17 -> 21190 | N33: =바닥판단가!G7 + 바닥판단가!G17 -> 76885
A34: GRP | B34: 기본형 | C34: 코너형 | D34: 샤워형 | E34: 구분 | F34: 1400 | G34: 2100 | H34: 1400 | I34: 1300 | J34: 900 | K34: 800 | L34: =바닥판단가!G6 -> 53600 | M34: =바닥판단가!G19 -> 23494 | N34: =바닥판단가!G6 + 바닥판단가!G19 -> 77094
A35: GRP | B35: 기본형 | C35: 코너형 | D35: 샤워형 | E35: 구분 | F35: 1400 | G35: 2100 | H35: 1400 | I35: 1400 | J35: 900 | K35: 700 | L35: =바닥판단가!G7 -> 55695 | M35: =바닥판단가!G18 -> 22342 | N35: =바닥판단가!G7 + 바닥판단가!G18 -> 78037
A36: GRP | B36: 기본형 | C36: 코너형 | D36: 샤워형 | E36: 구분 | F36: 1400 | G36: 2100 | H36: 1400 | I36: 1500 | J36: 850 | K36: 600 | L36: =바닥판단가!G8 -> 57581 | M36: =바닥판단가!G16 -> 20666 | N36: =바닥판단가!G8 + 바닥판단가!G16 -> 78247
A37: GRP | B37: 기본형 | C37: 코너형 | D37: 샤워형 | E37: 구분 | F37: 1400 | G37: 2100 | H37: 1400 | I37: 1500 | J37: 900 | K37: 600 | L37: =바닥판단가!G8 -> 57581 | M37: =바닥판단가!G17 -> 21190 | N37: =바닥판단가!G8 + 바닥판단가!G17 -> 78771
A38: GRP | B38: 기본형 | C38: 코너형 | D38: 샤워형 | E38: 구분 | F38: 1400 | G38: 2200 | H38: 1400 | I38: 1300 | J38: 900 | K38: 900 | L38: =바닥판단가!G6 -> 53600 | M38: =바닥판단가!G20 -> 25066 | N38: =바닥판단가!G6 + 바닥판단가!G20 -> 78666
A39: GRP | B39: 기본형 | C39: 코너형 | D39: 샤워형 | E39: 구분 | F39: 1400 | G39: 2200 | H39: 1400 | I39: 1300 | J39: 1000 | K39: 900 | L39: =바닥판단가!G6 -> 53600 | M39: =바닥판단가!G23 -> 27161 | N39: =바닥판단가!G6 + 바닥판단가!G23 -> 80761
A40: GRP | B40: 기본형 | C40: 코너형 | D40: 샤워형 | E40: 구분 | F40: 1400 | G40: 2200 | H40: 1400 | I40: 1400 | J40: 900 | K40: 800 | L40: =바닥판단가!G7 -> 55695 | M40: =바닥판단가!G19 -> 23494 | N40: =바닥판단가!G7 + 바닥판단가!G19 -> 79189
...

Sheet 바닥판단가
A1: 소재 | B1: 구조 | C1: 형태 | D1: 욕실공간 | E1: 폭 | F1: 길이 | G1: 단가 | H1: 비고
A2: GRP | B2: 기본형 | C2: 코너형 | D2: 세면부 | E2: 1300 | F2: 1300 | G2: 51610 | H2: 251106업데이트
A3: GRP | B3: 기본형 | C3: 코너형 | D3: 세면부 | E3: 1300 | F3: 1400 | G3: 53600
A4: GRP | B4: 기본형 | C4: 코너형 | D4: 세면부 | E4: 1300 | F4: 1500 | G4: 55485
A5: GRP | B5: 기본형 | C5: 코너형 | D5: 세면부 | E5: 1300 | F5: 1600 | G5: 57790
A6: GRP | B6: 기본형 | C6: 코너형 | D6: 세면부 | E6: 1400 | F6: 1300 | G6: 53600
A7: GRP | B7: 기본형 | C7: 코너형 | D7: 세면부 | E7: 1400 | F7: 1400 | G7: 55695
A8: GRP | B8: 기본형 | C8: 코너형 | D8: 세면부 | E8: 1400 | F8: 1500 | G8: 57581
A9: GRP | B9: 기본형 | C9: 코너형 | D9: 세면부 | E9: 1400 | F9: 1600 | G9: 59676
A10: GRP | B10: 기본형 | C10: 코너형 | D10: 세면부 | E10: 1500 | F10: 1300 | G10: 55485
A11: GRP | B11: 기본형 | C11: 코너형 | D11: 세면부 | E11: 1500 | F11: 1400 | G11: 57581
A12: GRP | B12: 기본형 | C12: 코너형 | D12: 세면부 | E12: 1500 | F12: 1500 | G12: 59676
A13: GRP | B13: 기본형 | C13: 코너형 | D13: 세면부 | E13: 1500 | F13: 1600 | G13: 61771
A14: GRP | B14: 기본형 | C14: 코너형 | D14: 세면부 | E14: 1600 | F14: 1300 | G14: 57790
A15: GRP | B15: 기본형 | C15: 코너형 | D15: 세면부 | E15: 1600 | F15: 1250 | G15: 130000 | H15: 대림 구매품
A16: GRP | B16: 기본형 | C16: 코너형 | D16: 샤워부 | E16: 600 | F16: 850 | G16: 20666
A17: GRP | B17: 기본형 | C17: 코너형 | D17: 샤워부 | E17: 600 | F17: 900 | G17: 21190
A18: GRP | B18: 기본형 | C18: 코너형 | D18: 샤워부 | E18: 700 | F18: 900 | G18: 22342
A19: GRP | B19: 기본형 | C19: 코너형 | D19: 샤워부 | E19: 800 | F19: 900 | G19: 23494
A20: GRP | B20: 기본형 | C20: 코너형 | D20: 샤워부 | E20: 900 | F20: 900 | G20: 25066
A21: GRP | B21: 기본형 | C21: 코너형 | D21: 샤워부 | E21: 900 | F21: 950 | G21: 0 | H21: 대림 구매품
A22: GRP | B22: 기본형 | C22: 코너형 | D22: 샤워부 | E22: 950 | F22: 900 | G22: 26113
A23: GRP | B23: 기본형 | C23: 코너형 | D23: 샤워부 | E23: 900 | F23: 1000 | G23: 27161
A24: GRP | B24: 기본형 | C24: 코너형 | D24: 샤워부 | E24: 1000 | F24: 1000 | G24: 29256
A25: FRP | B25: 기본형 | C25: 코너형 | D25: 세면부 | E25: 1200 | F25: 1450 | G25: 50000
A26: FRP | B26: 기본형 | C26: 코너형 | D26: 세면부 | E26: 1200 | F26: 1500 | G26: 50001
A27: FRP | B27: 기본형 | C27: 코너형 | D27: 세면부 | E27: 1300 | F27: 1500 | G27: 50002
A28: FRP | B28: 기본형 | C28: 코너형 | D28: 세면부 | E28: 1400 | F28: 1500 | G28: 50003
A29: FRP | B29: 기본형 | C29: 코너형 | D29: 세면부 | E29: 1600 | F29: 1500 | G29: 50004
A30: FRP | B30: 기본형 | C30: 코너형 | D30: 세면부 | E30: 1250 | F30: 1600 | G30: 50005
A31: FRP | B31: 기본형 | C31: 코너형 | D31: 세면부 | E31: 1300 | F31: 1600 | G31: 50006
A32: FRP | B32: 기본형 | C32: 코너형 | D32: 세면부 | E32: 1600 | F32: 1300 | G32: 50007
A33: FRP | B33: 기본형 | C33: 코너형 | D33: 세면부 | E33: 1350 | F33: 1600 | G33: 50008
... A75: GRP | B75: 타일일체형 | C75: 사각형 | D75: 욕조형 | E75: 19000 | F75: 1900 | G75: 98698

Sheet 천장판
A1: 판넬/점검구 | B1: 품명 | C1: 폭 | D1: 길이 | E1: 소계
A2: 바디판넬 | B2: SI-2 | C2: 2000 | D2: 1300 | E2: =ROUND(24876.5284210526,0) -> 24877
A3: 바디판넬 | B3: SI-3 | C3: 1750 | D3: 1300 | E3: =ROUND(19466.644754386,0) -> 19467
A4: 바디판넬 | B4: SI-4 | C4: 1750 | D4: 1350 | E4: =ROUND(20465.029754386,0) -> 20465
A5: 바디판넬 | B5: SI-5 | C5: 1750 | D5: 1350 | E5: =ROUND(22778.035754386,0) -> 22778
A6: 바디판넬 | B6: SI-6 | C6: 1750 | D6: 1450 | E6: =ROUND(22090.7790877193,0) -> 22091
A7: 바디판넬 | B7: SI-7 | C7: 1750 | D7: 1000 | E7: =ROUND(22305.1613333333,0) -> 22305
A8: 바디판넬 | B8: SI-8 | C8: 1750 | D8: 1200 | E8: =ROUND(25853.7433333333,0) -> 25854
A9: 바디판넬 | B9: SI-9 | C9: 2000 | D9: 1200 | E9: =ROUND(31177.068,0) -> 31177
A10: 바디판넬 | B10: SI-10 | C10: 1850 | D10: 1370 | E10: =ROUND(22090.7790877193,0) -> 22091
A11: 바디판넬 | B11: SI-11 | C11: 1850 | D11: 1260 | E11: =ROUND(21026.4810877193,0) -> 21026
A12: 사이드판넬 | B12: 700 | C12: 1750 | D12: 700 | E12: =ROUND(14109.9616666667,0) -> 14110
A13: 사이드판넬 | B13: 800 | C13: 1750 | D13: 800 | E13: =ROUND(15953.6971111111,0) -> 15954
A14: 사이드판넬 | B14: 900a | C14: 1750 | D14: 900 | E14: =ROUND(18683.766,0) -> 18684
A15: 사이드판넬 | B15: 900b | C15: 960 | D15: 900 | E15: =ROUND(10785.7126666667,0) -> 10786
A16: 사이드판넬 | B16: 1000 | C16: 1750 | D16: 1000 | E16: =ROUND(19905.1613333333,0) -> 19905
A17: 사이드판넬 | B17: 1200 | C17: 1750 | D17: 1200 | E17: =ROUND(23453.7433333333,0) -> 23454
A18: 사이드판넬 | B18: 2000 | C18: 2000 | D18: 1200 | E18: =ROUND(28777.068,0) -> 28777
A19: 사이드판넬 | B19: 750 | C19: 1850 | D19: 750 | E19: =ROUND(14527.649,0) -> 14528
A20: 사이드판넬 | B20: 1100 | C20: 1850 | D20: 1100 | E20: =ROUND(20189.7306666667,0) -> 20190
A21: 점검구 | B21: SI-2 | C21: 900 | D21: 700 | E21: =ROUND(8585.984,0) -> 8586
A22: 점검구 | B22: SI-3 | C22: 900 | D22: 700 | E22: =ROUND(8585.984,0) -> 8586
A23: 점검구 | B23: SI-4 | C23: 900 | D23: 700 | E23: =ROUND(8585.984,0) -> 8586
A24: 점검구 | B24: SI-5 | C24: 650 | D24: 500 | E24: =ROUND(6296.838,0) -> 6297
A25: 점검구 | B25: SI-6 | C25: 900 | D25: 700 | E25: =ROUND(8585.984,0) -> 8586
A26: 점검구 | B26: SI-7 | C26: 450 | D26: 450 | E26: =ROUND(4728.38884210526,0) -> 4728
A27: 점검구 | B27: SI-8 | C27: 450 | D27: 450 | E27: =ROUND(4728.38884210526,0) -> 4728
A28: 점검구 | B28: SI-9 | C28: 450 | D28: 450 | E28: =ROUND(4728.38884210526,0) -> 4728
A29: 점검구 | B29: SI-10 | C29: 900 | D29: 650 | E29: =ROUND(8174.96333333333,0) -> 8175
A30: 점검구 | B30: SI-11 | C30: 900 | D30: 750 | E30: =ROUND(8184.748,0) -> 8185

Sheet 천장판타공
A1: 품목 | B1: 단가 | C1: 비고
A2: 바디 | B2: 1500 | C2: 2인 40EA/시간(1면절단)
A3: 사이드 | B3: 1500 | C3: 2인 40EA/시간(1면절단)
A4: 환풍기홀 | B4: 4000 | C4: 2인 15EA/시간(1개)
A5: 사각매립등 | B5: 4000 | C5: 2인 15EA/시간(1개)
A6: 원형등 | B6: 2000 | C6: 2인 35EA/시간(1개)
A7: 직선1회 | B7: 1500 | C7: 2인 40EA/시간

Sheet 자재단가내역
A1: 품목 | B1: 분류 | C1: 사양 및 규격 | D1: 단가 | E1: 수량
A2: 바닥판 | B2: GRP부재료 | C2: 철판평자 | D2: 1500 | E2: 2
A3: 바닥판 | B3: GRP부재료 | C3: 철판ㄱ자 | D3: 2000 | E3: 2
A4: 바닥판 | B4: GRP부재료 | C4: 에폭시본드 | D4: 3150 | E4: 1
A5: 바닥판 | B5: GRP부재료 | C5: 방수테입 | D5: 500 | E5: 1
A6: 바닥판 | B6: GRP부재료 | C6: 기타 | D6: 1000 | E6: 1
A7: 바닥판 | B7: GRP/FRP 부재료 | C7: 배수트랩 층하용 | D7: 4000 | E7: 2
A8: 바닥판 | B8: GRP/FRP 부재료(내화채움용) | C8: 배수트랩 층하용, 대림용 | D8: 6500 | E8: 2
A9: 바닥판 | B9: GRP/FRP 부재료 | C9: 배수트랩 층상용 1구가지관 | D9: 6500 | E9: 1
A10: 바닥판 | B10: GRP/FRP 부재료 | C10: 배수트랩 층상용 2구가지관 | D10: 6500 | E10: 1
A11: 바닥판 | B11: GRP/FRP 부재료 | C11: 배수트랩 층상용 3구가지관 | D11: 6500 | E11: 1
A12: 바닥판 | B12: GRP 부재료 | C12: 드레인커버 세면부용(성일용) | D12: 3950 | E12: 1
A13: 바닥판 | B13: GRP 부재료 | C13: 드레인커버 샤워실용(성일용) | D13: 4600 | E13: 1
... A40: 벽판 | B40: PU타일 벽체 | C40: PU벽판 | D40: 30000 | E40: 1
A41: 타일 | B41: PU타일 벽체 타일 | C41: 벽타일 250*400 | D41: =18000/15 -> 1200 | E41: 1
A42: 타일 | B42: PU타일 벽체 타일 | C42: 벽타일 300*600 | D42: =18000/9 -> 2000 | E42: 1
A43: 오,배수 배관 | B43: GRP/FRP/PP/PE 부재료 | C43: 직관(Φ100) | D43: 2875 | E43: 1
A44: 오,배수 배관 | B44: GRP/FRP/PP/PE 부재료 | C44: 직관(Φ75) | D44: 450 | E44: 2
A45: 오,배수 배관 | B45: GRP/FRP/PP/PE 부재료 | C45: 직관(Φ50) | D45: 906 | E45: 2
A46: 오,배수 배관 | B46: GRP/FRP/PP/PE 부재료 | C46: 엘보(Φ100) | D46: 11500 | E46: 1
A47: 오,배수 배관 | B47: GRP/FRP/PP/PE 부재료 | C47: 엘보(Φ50) | D47: 2900 | E47: 2
A48: 오,배수 배관 | B48: GRP/FRP/PP/PE 부재료 | C48: 엘보(Φ35) | D48: 2500 | E48: 1
A49: 오,배수 배관 | B49: GRP/FRP/PP/PE 부재료 | C49: 직관(Φ100) | D49: 500 | E49: 1
A50: 오,배수 배관 | B50: GRP/FRP/PP/PE 부재료 | C50: PVC 접착제 | D50: 5000 | E50: 0.2
A51: 오,배수 배관 | B51: PP/PE 부재료, 레듀샤 | C51: Φ100 → Φ50 | D51: 2500 | E51: 2
A52: 오,배수 배관 | B52: 설비업체 이관 | C52: 현장별 개별 견적 | E52: 1
A53: 오,배수 배관 | B53: 오수구 소켓(내화용) | C53: Φ100, 대림용 | D53: 7000 | E53: 1
A54: 오,배수 배관 | B54: 내화채움 오수조인트(내화용) | C54: Φ100, 대림용 | D54: 7500 | E54: 1
A55: 오,배수 배관 | B55: 내화채움 배수조인트(내화용) | C55: Φ50, 대림용 | D55: 4500 | E55: 2
A56: 냉온수배관 | B56: 냉온수배관 | C56: PB 독립배관 | D56: 5000 | E56: 1
A57: 냉온수배관 | B57: 냉온수배관 | C57: PB 세대 세트 배관 | D57: 100000 | E57: 1
A58: 냉온수배관 | B58: 냉온수배관 | C58: PB+이중관(오픈수전함)(코너형) | D58: 85000 | E58: 1
A59: 냉온수배관 | B59: 냉온수배관 | C59: PB+이중관(오픈수전함)(사각형) | D59: 75000 | E59: 1
A60: 타일 | B60: 바닥타일 | C60: 바닥타일 200*200 | D60: =15000/37 -> 405.40541 | E60: 1
A61: 타일 | B61: 바닥타일 | C61: 바닥타일 300*300 | D61: =15000/16 -> 937.5 | E61: 1
A62: 천장판 | B62: GRP | C62: GRP천장판 | E62: 1
A63: 천장판 | B63: ABS | C63: ABS천장판, 현장별 견적 | E63: 1
A64: 문세트 | B64: PVC | C64: PVC 4방틀 (130 ~ 230바) | E64: 1
A65: 문세트 | B65: ABS | C65: ABS 문짝 | D65: 49500 | E65: 1
A66: 문세트 | B66: 하드웨어 | C66: 도어락 | D66: 12000 | E66: 1
...

Sheet 벽판
A1: variable | B1: value
A2: 프레임단가_15각 | B2: 1440
A3: 프레임단가_16각 | B3: 1485
A4: 프레임단가_19각 | B4: 1798
A5: P_U단가_15각 | B5: 3162
A6: P_U단가_16각 | B6: 3341
A7: P_U단가_19각 | B7: 3930
A8: 조립클립단가 | B8: 4320
A9: 설비감가비 | B9: 830
A10: 제조경비_판넬당 | B10: 434.60925
A11: 타일관리비_단가 | B11: 60
A12: 출고_렉입고_단가 | B12: 3730
A13: 생산인건비_일단가 | B13: 256000 | J13: 269000
A14: 프레임_LOSS_배수 | B14: 1.02
A15: 벽체높이_기본_m | B15: 2.2 | J15: 2.3
A16: 기준생산량_1_5이하 | B16: 325
A17: 기준생산량_1_51_1_89 | B17: 300
A18: 기준생산량_1_9이상 | B18: 275
A19: 시급_1_5이하 | B19: 8000
A20: 시급_1_51_1_89 | B20: 9000
A21: 시급_1_9이상 | B21: 10000
A22: 도어폭_0_7m | B22: 0.7
A23: 도어폭_0_8m | B23: 0.8

Sheet PVE
A1: PVE 욕실 유형 | B1: 원재료비 | C1: 가공비
A2: 일반형 | B2: 12000 | C2: 24331
A3: 욕실선반형 | B3: 12000 | C3: 31159

Sheet 접착제
A1: 바닥타일 면적 | B1: 접착제 단가
A2: ㎡ | B2: 2146

Sheet 데이터 설명
A1: Sungil DB는 바닥판 원가, 천장판 원가 등을 담은 8개의 sheet로 구성되어 있음.
A2: 바닥판단가 (바닥판 단가 “기준표/룩업 테이블”)
A3: 주요 컬럼: 소재, 구조, 형태, 욕실공간, 폭, 길이, 단가, 비고
A4: 용도: 코드에서 보통 **(소재/구조/형태/공간/폭/길이)**로 매칭해서 단가를 가져옮.
A5: 바닥판 단가
A6: 컬럼 | B6: 타입 | C6: 단위 | D6: 예시 | E6: 설명
A7: 소재 | B7: string | C7: - | D7: GRP | E7: 바닥판 소재 구분(GRP/FRP). PVE는 GRP/FRP가 아닌 경우에 선택하게 됨
A8: 구조 | B8: string | C8: - | D8: 기본형 | E8: 제품 구조/배수/일체형 구분
A9: 형태 | B9: string | C9: - | D9: 코너형 | E9: 욕실 형태(코너/사각/욕조 등)
A10: 욕실공간 | B10: string | C10: - | D10: 세면부 | E10: 적용 구간(세면/샤워/단차없음/샤워형/욕조형 등)
A11: 폭 | B11: int | C11: mm | D11: 1300 | E11: 바닥판 폭
A12: 길이 | B12: int | C12: mm | D12: 1500 | E12: 바닥판 길이
A13: 단가 | B13: int | C13: KRW | D13: 51610 | E13: 단가(원).
A15: 바닥판 (욕실 규격별 “조합 완성 단가표”)
A16: 특징: 소재는 GRP/FRP, 유형은 기본형/중앙배수/일체형/타일일체형, 형태는 사각형/코너형, 용도는 샤워형/욕조형, 경계는 구분/구분없음 값이 있음
A17: 바닥판단가를 바탕으로, 욕실 입력조건(욕실폭/길이, 세면부·샤워부 폭·길이 등)에 따라 세면부 단가 + 샤워부 단가 = 소계가 계산되어 정리된 표
A18: 바닥판
A19: 컬럼 | B19: 타입 | C19: 단위 | D19: 허용값/예시 | E19: 설명
A20: 소재 | B20: string | C20: - | D20: GRP, FRP | E20: 바닥판 소재
A21: 유형 | B21: string | C21: - | D21: 기본형, 중앙배수, 일체형, 타일일체형 | E21: 구조/제품 타입
A22: 형태 | B22: string | C22: - | D22: 코너형, 사각형 | E22: 욕실 형태
A23: 용도 | B23: string | C23: - | D23: 샤워형, 욕조형 | E23: 욕실 용도 구분
A24: 경계 | B24: string | C24: - | D24: 구분, 구분없음 | E24: 세면/샤워 구분 여부
A25: 욕실폭 | B25: int | C25: mm | D25: 1300 | E25: 전체 욕실 폭
A26: 욕실길이 | B26: int | C26: mm | D26: 1900 | E26: 전체 욕실 길이
A27: 세면부폭 | B27: int/NaN | C27: mm | D27: 1300 또는 NaN | E27: 경계=구분일 때만 채움, NaN은 결측치
A28: 세면부길이 | B28: int/NaN | C28: mm | D28: 1400 또는 NaN | E28: 경계=구분일 때만 채움
A29: 샤워부폭 | B29: int/NaN | C29: mm | D29: 900 또는 NaN | E29: 경계=구분일 때만 채움
A30: 샤워부길이 | B30: int/NaN | C30: mm | D30: 700 또는 NaN | E30: 경계=구분일 때만 채움
A31: 세면부바닥판 단가 | B31: int/NaN | C31: KRW | D31: 51610 또는 NaN | E31: 세면부 바닥판 단가(원)
A32: 샤워부바닥판 단가 | B32: int/NaN | C32: KRW | D32: 20666 또는 NaN | E32: 샤워부 바닥판 단가(원)
A33: 소계 | B33: int | C33: KRW | D33: 72276 | E33: 최종 합계 단가(원)
A35: 바닥판 소재가 PVE로 결정될 때 쓰는 PVE 전용 비용
A36: PVE
A37: 컬럼명 | B37: 타입 | C37: 단위 | D37: 예시 | E37: 설명
A38: PVE 욕실 유형 | B38: string | C38: - | D38: 일반형 | E38: PVE 욕실유형은 일반형과 욕실선반형 2가지가 있음
A39: 원재료비 | B39: int | C39: KRW | D39: 12000 | E39: ㎡당 12,000원
A40: 가공비 | B40: int | C40: KRW | D40: 1000 | E40: 일반형 24,331원, 욕실선반형 31,159원
A42: 천장판 (천장판 카탈로그: 바디/사이드/점검구)
A43: 용도: 천장판 조합/매칭(바디판넬, 사이드판넬, 점검구) 선택 시 가격 산정의 기준 데이터.
...
